Workbook

Sheet Eagle View
B82: Total Net Worth
A165: INVESTING
A250: Money Flow Repartition

Sheet Headquarters
B3: Recurring Expenses | M3: Expenses Per Month
C4: Amount | D4: Frequency | E4: Next Due Date | F4: Type | G4: Where ? | H4: Split | I4: Pay Cycle (Tuesday) | J4: Weeks Left | K4: Current Statut | M4: Student Loan | N4: Optus | O4: iCloud | P4: Youtube Premium | Q4: Microsoft Office | R4: ChatGPT | S4: Claude AI | T4: Total
B5: Optus | C5: 55 | D5: Monthly | E5: 46148 | F5: Bill | G5: Westpac Choice | H5: Solo to Bill | I5: 46175 | J5: =MAX(0, ROUNDUP(($I5-TODAY())/7, 0)) -> 3 | K5: Not Funded | M5: 110 | N5: 55 | O5: 14.99 | P5: 23 | Q5: 16 | R5: 29.99 | S5: 34 | T5: =SUM(N5:S5) -> 172.98
B6: ChatGPT | C6: 29.99 | D6: Monthly | E6: 46179 | F6: Subscription | G6: Westpac Choice | H6: Solo to Bill | I6: 46175 | J6: =MAX(0, ROUNDUP(($I6-TODAY())/7, 0)) -> 3 | K6: Not Funded
B7: Microsoft Office | C7: 16 | D7: Monthly | E7: 46148 | F7: Subscription | G7: Westpac Choice | H7: Solo to Bill | I7: 46175 | J7: =MAX(0, ROUNDUP(($I7-TODAY())/7, 0)) -> 3 | K7: Not Funded | M7: Expenses Per Week
B8: Youtube Premium | C8: 22.99 | D8: Monthly | E8: 46152 | F8: Subscription | G8: Westpac Choice | H8: Solo to Bill | I8: 46147 | J8: =MAX(0, ROUNDUP(($I8-TODAY())/7, 0)) -> 0 | K8: Not Funded | M8: Real Expenses | N8: Household Expenses | O8: Total
B9: Google One | C9: 3.5 | D9: Monthly | E9: 46162 | F9: Subscription | G9: Compte Courant | H9: Solo to French Acc | I9: 46189 | J9: =MAX(0, ROUNDUP(($I9-TODAY())/7, 0)) -> 5 | K9: Funded until June 20 | M9: ='Money Flow'!D577 -> 331.53688 | N9: ='Money Flow'!G577 -> 258.29625 | O9: =SUM(M9:N9) -> 589.83313
B10: Student Loan | C10: 113 | D10: Monthly | E10: 46193 | F10: Reimbursement | G10: Compte Courant | H10: Solo to French Acc | I10: 46189 | J10: =MAX(0, ROUNDUP(($I10-TODAY())/7, 0)) -> 5 | K10: Funded until June 20
B11: Claude AI | C11: 34 | D11: Monthly | E11: 46168 | F11: Subscription | G11: Westpac Choice | H11: Solo to Bill | I11: 46163 | J11: =MAX(0, ROUNDUP(($I11-TODAY())/7, 0)) -> 1 | K11: Not Funded
B12: Icloud | C12: 14.99 | D12: Monthly | E12: 46170 | F12: Subscription | G12: Westpac Choice | H12: Solo to Bill | I12: 46163 | J12: =MAX(0, ROUNDUP(($I12-TODAY())/7, 0)) -> 1 | K12: Not Funded
B13: Rent | C13: 150 | D13: Weekly | E13: 46161 | F13: Rent | G13: Westpac Choice | H13: Solo to Lily | I13: 46161 | J13: =MAX(0, ROUNDUP(($I13-TODAY())/7, 0)) -> 1 | K13: Not Funded
B14: Groceries (Joint Account) | C14: 200 | D14: Weekly | E14: 46161 | F14: Groce./Activ. | G14: Joint Acc | H14: Solo to Joint | I14: 46161 | J14: =MAX(0, ROUNDUP(($I14-TODAY())/7, 0)) -> 1 | K14: Not Funded
J17: Next Pay Day | K17: 46161
B20: Goal And Timelines
B21: Goal | C21: Type | D21: Current Amount | E21: Targeted Amount | F21: Remaining Amount | G21: Weekly Save Needed | H21: Targeted Date | I21: Weeks Left | J21: Progress (%) | K21: Priority
B22: Money To Move in Sydney | C22: Short Term | D22: 4015 | E22: 8000 | F22: =IF(E22="","", E22-D22) -> 3985 | G22: =IF($I22<=0, $F22, ROUND($F22/$I22,0)) -> 797 | H22: 46189 | I22: =MAX(0, ROUNDUP(($H22-TODAY())/7, 0)) -> 5 | J22: =IF($E22=0, 0, $D22/$E22) -> 0.501875 | K22: High
B23: Student Loan | C23: Medium Term | D23: =H44 -> 2445.5847 | E23: =J33 -> 8126 | F23: =IF(E23="","", E23-D23) -> 5680.4153 | G23: =IF($I23<=0, $F23, ROUND($F23/$I23,0)) -> 80 | H23: 46650 | I23: =MAX(0, ROUNDUP(($H23-TODAY())/7, 0)) -> 71 | J23: =IF($E23=0, 0, $D23/$E23) -> 0.300958 | K23: Medium
B24: Phiphi Reimbursement | C24: Medium Term | D24: 0 | E24: =D44 -> 1706.46 | F24: =IF(E24="","", E24-D24) -> 1706.46 | G24: =IF($I24<=0, $F24, ROUND($F24/$I24,0)) -> 24 | H24: 46650 | I24: =MAX(0, ROUNDUP(($H24-TODAY())/7, 0)) -> 71 | J24: =IF($E24=0, 0, $D24/$E24) -> 0 | K24: Medium
B25: Cash Buffer (Stage 2) | C25: Medium Term | D25: =C83 -> 1500 | E25: 10000 | F25: =IF(E25="","", E25-D25) -> 8500 | G25: =IF($I25<=0, $F25, ROUND($F25/$I25,0)) -> 258 | H25: 46386 | I25: =MAX(0, ROUNDUP(($H25-TODAY())/7, 0)) -> 33 | J25: =IF($E25=0, 0, $D25/$E25) -> 0.15 | K25: High
B26: House | C26: Long Term | D26: 0 | E26: 100000 | F26: =IF(E26="","", E26-D26) -> 100000 | G26: =IF($I26<=0, $F26, ROUND($F26/$I26,0)) -> 2174 | H26: 46478 | I26: =MAX(0, ROUNDUP(($H26-TODAY())/7, 0)) -> 46 | J26: =IF($E26=0, 0, $D26/$E26) -> 0 | K26: Low
B27: Investment | C27: Long Term | D27: =C86 -> 872.22531 | E27: 1000000 | F27: =IF(E27="","", E27-D27) -> 999127.77 | G27: =IF($I27<=0, $F27, ROUND($F27/$I27,0)) -> 1151 | H27: 52230 | I27: =MAX(0, ROUNDUP(($H27-TODAY())/7, 0)) -> 868 | J27: =IF($E27=0, 0, $D27/$E27) -> 0.00087222531 | K27: Low
B30: Student Loan
B31: Date | C31: Phiphi's Contribution | E31: My contribution | G31: Prélévement | I31: Loan Total Value / Remaining
C32: Eur | D32: Aud | E32: Eur | F32: Aud | G32: Eur | H32: Aud | I32: Eur | J32: Aud
B33: Rule | C33: 150 | D33: =C33*K78 -> 243.78 | E33: =G33-C33 -> 64.97 | F33: =E33*K78 -> 105.58924 | G33: 214.97 | H33: =G33*K78 -> 349.36924 | I33: 5000 | J33: =I33*K78 -> 8126
B34: 45950 | C34: 150 | D34: =C34*K78 -> 243.78 | E34: =G34-C34 -> 64.97 | F34: =E34*K78 -> 105.58924 | G34: 214.97 | H34: =G34*K78 -> 349.36924 | I34: =I33-G34 -> 4785.03 | J34: =J33-H34 -> 7776.6308
B35: 45981 | C35: 150 | D35: =C35*K78 -> 243.78 | E35: =G35-C35 -> 64.97 | F35: =E35*K78 -> 105.58924 | G35: 214.97 | H35: =G35*K78 -> 349.36924 | I35: =I34-G35 -> 4570.06 | J35: =J34-H35 -> 7427.2615
B36: 46011 | C36: 150 | D36: =C36*K78 -> 243.78 | E36: =G36-C36 -> 64.97 | F36: =E36*K78 -> 105.58924 | G36: 214.97 | H36: =G36*K78 -> 349.36924 | I36: =I35-G36 -> 4355.09 | J36: =J35-H36 -> 7077.8923
B37: 46042 | C37: 150 | D37: =C37*K78 -> 243.78 | E37: =G37-C37 -> 64.97 | F37: =E37*K78 -> 105.58924 | G37: 214.97 | H37: =G37*K78 -> 349.36924 | I37: =I36-G37 -> 4140.12 | J37: =J36-H37 -> 6728.523
B38: 46073 | C38: 150 | D38: =C38*K78 -> 243.78 | E38: =G38-C38 -> 64.97 | F38: =E38*K78 -> 105.58924 | G38: 214.97 | H38: =G38*K78 -> 349.36924 | I38: =I37-G38 -> 3925.15 | J38: =J37-H38 -> 6379.1538
B39: 46101 | C39: 150 | D39: =C39*K78 -> 243.78 | E39: =G39-C39 -> 64.97 | F39: =E39*K78 -> 105.58924 | G39: 214.97 | H39: =G39*K78 -> 349.36924 | I39: 3769.85 | J39: =J38-H39 -> 6029.7845
B40: 46132 | C40: 150 | D40: =C40*K78 -> 243.78 | E40: =G40-C40 -> 64.97 | F40: =E40*K78 -> 105.58924 | G40: 214.97 | H40: =G40*K78 -> 349.36924 | I40: =I39-G40 -> 3554.88 | J40: =J39-H40 -> 5680.4153
B41: 46162
B42: 46193
B43: 46223
B44: Total / Remaining | C44: =SUM(C34:C43) -> 1050 | D44: =SUM(D34:D43) -> 1706.46 | E44: =SUM(E34:E43) -> 454.79 | F44: =SUM(F34:F43) -> 739.12471 | G44: =SUM(G34:G43) -> 1504.79 | H44: =SUM(H34:H43) -> 2445.5847 | I44: =I40 -> 3554.88 | J44: =J40 -> 5680.4153
B47: Bank Statut (including Joint Acc)
C48: WestPac | E48: Commonwealth Bank | J48: LaBanque Postale
C49: Choice | D49: eSaver | E49: Daily Spending Acc | F49: Joint Expenses Acc | G49: Planned Expenses Acc | H49: Investing Cash Acc | I49: Emergency Fund Acc | J49: Compte Courant | K49: Livret Jeune | L49: Net Worth
B50: 24/1/2026 - 3pm | C50: 117.49 | D50: 15.03 | E50: 0 | F50: 202.62 | G50: 50.01 | H50: 0 | I50: 50.01 | J50: =7*K78 -> 11.3764 | K50: =12*K78 -> 19.5024 | L50: =SUM(C50:K50) -> 466.0388 | M50: 24/1/2026 - 3pm
...

Sheet Money Flow
B2: FLOW OF THE WEEK
B3: Week | C3: Date | D3: Description | E3: Flow Type | F3: Source Account | G3: Destination Account | H3: Amount | I3: Category (Economic Role) | N3: Real Expense Amt | O3: Internal Transfer Amt | P3: Saving Allocation Amt | Q3: Investment Amt | R3: Debt Repayment Amt | S3: Joint Account Amt | T3: Income Amt
A4: 27/1/26 -> 2/2/26 | B4: 27/1/26 -> 2/2/26 | C4: 46049 | D4: Pay Sapien | E4: Income | F4: Sapien | G4: WestPac Everyday | H4: 1316.75 | I4: Salary | N4: =IF(OR(E4="Personal Expense",E4="Recurring Expense"),H4,0) -> 0 | O4: =IF(E4="Internal Transfer",H4,0) -> 0 | P4: =IF(E4="Saving Allocation",H4,0) -> 0 | Q4: =IF(E4="Investment",H4,0) -> 0 | R4: =IF(E4="Debt Repayment",H4,0) -> 0 | S4: =IF(E4="Joint Account",H4,0) -> 0 | T4: =IF(E4="Income",H4,0) -> 1316.75
A5: 27/1/26 -> 2/2/26 | C5: 46049 | D5: Bills Contribution | E5: Recurring Expense | F5: WestPac Everyday | G5: Lily | H5: 150 | I5: Rent | N5: =IF(OR(E5="Personal Expense",E5="Recurring Expense"),H5,0) -> 150 | O5: =IF(E5="Internal Transfer",H5,0) -> 0 | P5: =IF(E5="Saving Allocation",H5,0) -> 0 | Q5: =IF(E5="Investment",H5,0) -> 0 | R5: =IF(E5="Debt Repayment",H5,0) -> 0 | S5: =IF(E5="Joint Account",H5,0) -> 0 | T5: =IF(E5="Income",H5,0) -> 0
A6: 27/1/26 -> 2/2/26 | C6: 46049 | D6: Reimboursement Lily | E6: Debt Repayment | F6: WestPac Everyday | G6: Lily | H6: 375 | I6: Debt | N6: =IF(OR(E6="Personal Expense",E6="Recurring Expense"),H6,0) -> 0 | O6: =IF(E6="Internal Transfer",H6,0) -> 0 | P6: =IF(E6="Saving Allocation",H6,0) -> 0 | Q6: =IF(E6="Investment",H6,0) -> 0 | R6: =IF(E6="Debt Repayment",H6,0) -> 375 | S6: =IF(E6="Joint Account",H6,0) -> 0 | T6: =IF(E6="Income",H6,0) -> 0
A7: 27/1/26 -> 2/2/26 | C7: 46049 | D7: Transfer To Joint Account | E7: Joint Account | F7: WestPac Everyday | G7: Joint Account | H7: 200 | I7: Housing | N7: =IF(OR(E7="Personal Expense",E7="Recurring Expense"),H7,0) -> 0 | O7: =IF(E7="Internal Transfer",H7,0) -> 0 | P7: =IF(E7="Saving Allocation",H7,0) -> 0 | Q7: =IF(E7="Investment",H7,0) -> 0 | R7: =IF(E7="Debt Repayment",H7,0) -> 0 | S7: =IF(E7="Joint Account",H7,0) -> 200 | T7: =IF(E7="Income",H7,0) -> 0
A8: 27/1/26 -> 2/2/26 | C8: 46049 | D8: BTC Buy | E8: Investment | F8: WestPac Everyday | G8: OKX | H8: 15 | I8: Investment | N8: =IF(OR(E8="Personal Expense",E8="Recurring Expense"),H8,0) -> 0 | O8: =IF(E8="Internal Transfer",H8,0) -> 0 | P8: =IF(E8="Saving Allocation",H8,0) -> 0 | Q8: =IF(E8="Investment",H8,0) -> 15 | R8: =IF(E8="Debt Repayment",H8,0) -> 0 | S8: =IF(E8="Joint Account",H8,0) -> 0 | T8: =IF(E8="Income",H8,0) -> 0
A9: 27/1/26 -> 2/2/26 | C9: 46050 | D9: Flight Ticket Sydney | E9: Personal Expense | F9: WestPac Everyday | G9: External | H9: 56.4 | I9: Transport | N9: =IF(OR(E9="Personal Expense",E9="Recurring Expense"),H9,0) -> 56.4 | O9: =IF(E9="Internal Transfer",H9,0) -> 0 | P9: =IF(E9="Saving Allocation",H9,0) -> 0 | Q9: =IF(E9="Investment",H9,0) -> 0 | R9: =IF(E9="Debt Repayment",H9,0) -> 0 | S9: =IF(E9="Joint Account",H9,0) -> 0 | T9: =IF(E9="Income",H9,0) -> 0
A10: 27/1/26 -> 2/2/26 | C10: 46051 | D10: Food at Work | E10: Personal Expense | F10: WestPac Everyday | G10: External | H10: 8 | I10: Food/Drink | N10: =IF(OR(E10="Personal Expense",E10="Recurring Expense"),H10,0) -> 8 | O10: =IF(E10="Internal Transfer",H10,0) -> 0 | P10: =IF(E10="Saving Allocation",H10,0) -> 0 | Q10: =IF(E10="Investment",H10,0) -> 0 | R10: =IF(E10="Debt Repayment",H10,0) -> 0 | S10: =IF(E10="Joint Account",H10,0) -> 0 | T10: =IF(E10="Income",H10,0) -> 0
A11: 27/1/26 -> 2/2/26 | C11: 46051 | D11: Icloud | E11: Recurring Expense | F11: WestPac Everyday | G11: External | H11: 14.99 | I11: Subscription | N11: =IF(OR(E11="Personal Expense",E11="Recurring Expense"),H11,0) -> 14.99 | O11: =IF(E11="Internal Transfer",H11,0) -> 0 | P11: =IF(E11="Saving Allocation",H11,0) -> 0 | Q11: =IF(E11="Investment",H11,0) -> 0 | R11: =IF(E11="Debt Repayment",H11,0) -> 0 | S11: =IF(E11="Joint Account",H11,0) -> 0 | T11: =IF(E11="Income",H11,0) -> 0
A12: 27/1/26 -> 2/2/26 | C12: 46052 | D12: Food at Work | E12: Personal Expense | F12: WestPac Everyday | G12: External | H12: 8 | I12: Food/Drink | N12: =IF(OR(E12="Personal Expense",E12="Recurring Expense"),H12,0) -> 8 | O12: =IF(E12="Internal Transfer",H12,0) -> 0 | P12: =IF(E12="Saving Allocation",H12,0) -> 0 | Q12: =IF(E12="Investment",H12,0) -> 0 | R12: =IF(E12="Debt Repayment",H12,0) -> 0 | S12: =IF(E12="Joint Account",H12,0) -> 0 | T12: =IF(E12="Income",H12,0) -> 0
A13: 27/1/26 -> 2/2/26 | C13: 46053 | D13: Buffer for Upcoming Bills | E13: Internal Transfer | F13: WestPac Everyday | G13: WestPac Savings | H13: 105 | I13: Buffer (To spend) | N13: =IF(OR(E13="Personal Expense",E13="Recurring Expense"),H13,0) -> 0 | O13: =IF(E13="Internal Transfer",H13,0) -> 105 | P13: =IF(E13="Saving Allocation",H13,0) -> 0 | Q13: =IF(E13="Investment",H13,0) -> 0 | R13: =IF(E13="Debt Repayment",H13,0) -> 0 | S13: =IF(E13="Joint Account",H13,0) -> 0 | T13: =IF(E13="Income",H13,0) -> 0
A14: 27/1/26 -> 2/2/26 | C14: 46053 | D14: Buffer for Dentist | E14: Personal Expense | F14: WestPac Everyday | G14: LaBanquePostale | H14: 100 | I14: Buffer (To spend) | N14: =IF(OR(E14="Personal Expense",E14="Recurring Expense"),H14,0) -> 100 | O14: =IF(E14="Internal Transfer",H14,0) -> 0 | P14: =IF(E14="Saving Allocation",H14,0) -> 0 | Q14: =IF(E14="Investment",H14,0) -> 0 | R14: =IF(E14="Debt Repayment",H14,0) -> 0 | S14: =IF(E14="Joint Account",H14,0) -> 0 | T14: =IF(E14="Income",H14,0) -> 0
A15: 27/1/26 -> 2/2/26 | C15: 46053 | D15: Sandwich Mama | E15: Personal Expense | F15: WestPac Everyday | G15: External | H15: 11 | I15: Food/Drink | N15: =IF(OR(E15="Personal Expense",E15="Recurring Expense"),H15,0) -> 11 | O15: =IF(E15="Internal Transfer",H15,0) -> 0 | P15: =IF(E15="Saving Allocation",H15,0) -> 0 | Q15: =IF(E15="Investment",H15,0) -> 0 | R15: =IF(E15="Debt Repayment",H15,0) -> 0 | S15: =IF(E15="Joint Account",H15,0) -> 0 | T15: =IF(E15="Income",H15,0) -> 0
A16: 27/1/26 -> 2/2/26 | C16: 46054 | D16: Buffer for Emerg. Cash | E16: Saving Allocation | F16: WestPac Everyday | G16: Emergency Fund | H16: 200 | I16: Savings | N16: =IF(OR(E16="Personal Expense",E16="Recurring Expense"),H16,0) -> 0 | O16: =IF(E16="Internal Transfer",H16,0) -> 0 | P16: =IF(E16="Saving Allocation",H16,0) -> 200 | Q16: =IF(E16="Investment",H16,0) -> 0 | R16: =IF(E16="Debt Repayment",H16,0) -> 0 | S16: =IF(E16="Joint Account",H16,0) -> 0 | T16: =IF(E16="Income",H16,0) -> 0
A17: 27/1/26 -> 2/2/26 | C17: 46054 | D17: Fitness weights | E17: Personal Expense | F17: WestPac Everyday | G17: External | H17: 60 | I17: Leisure | N17: =IF(OR(E17="Personal Expense",E17="Recurring Expense"),H17,0) -> 60 | O17: =IF(E17="Internal Transfer",H17,0) -> 0 | P17: =IF(E17="Saving Allocation",H17,0) -> 0 | Q17: =IF(E17="Investment",H17,0) -> 0 | R17: =IF(E17="Debt Repayment",H17,0) -> 0 | S17: =IF(E17="Joint Account",H17,0) -> 0 | T17: =IF(E17="Income",H17,0) -> 0
A18: 27/1/26 -> 2/2/26 | N18: =IF(OR(E18="Personal Expense",E18="Recurring Expense"),H18,0) -> 0 | O18: =IF(E18="Internal Transfer",H18,0) -> 0 | P18: =IF(E18="Saving Allocation",H18,0) -> 0 | Q18: =IF(E18="Investment",H18,0) -> 0 | R18: =IF(E18="Debt Repayment",H18,0) -> 0 | S18: =IF(E18="Joint Account",H18,0) -> 0 | T18: =IF(E18="Income",H18,0) -> 0
A19: 27/1/26 -> 2/2/26 | N19: =IF(OR(E19="Personal Expense",E19="Recurring Expense"),H19,0) -> 0 | O19: =IF(E19="Internal Transfer",H19,0) -> 0 | P19: =IF(E19="Saving Allocation",H19,0) -> 0 | Q19: =IF(E19="Investment",H19,0) -> 0 | R19: =IF(E19="Debt Repayment",H19,0) -> 0 | S19: =IF(E19="Joint Account",H19,0) -> 0 | T19: =IF(E19="Income",H19,0) -> 0
A20: 27/1/26 -> 2/2/26 | B20: Pay | H20: =SUMIF(E4:E17,"Income",H4:H17) -> 1316.75 | N20: =IF(OR(E20="Personal Expense",E20="Recurring Expense"),H20,0) -> 0 | O20: =IF(E20="Internal Transfer",H20,0) -> 0 | P20: =IF(E20="Saving Allocation",H20,0) -> 0 | Q20: =IF(E20="Investment",H20,0) -> 0 | R20: =IF(E20="Debt Repayment",H20,0) -> 0 | S20: =IF(E20="Joint Account",H20,0) -> 0 | T20: =IF(E20="Income",H20,0) -> 0
A21: 27/1/26 -> 2/2/26 | F21: Total Household Expenses | H21: =SUMIF(E4:E17,"Joint Account",H4:H17) -> 200 | N21: =IF(OR(E21="Personal Expense",E21="Recurring Expense"),H21,0) -> 0 | O21: =IF(E21="Internal Transfer",H21,0) -> 0 | P21: =IF(E21="Saving Allocation",H21,0) -> 0 | Q21: =IF(E21="Investment",H21,0) -> 0 | R21: =IF(E21="Debt Repayment",H21,0) -> 0 | S21: =IF(E21="Joint Account",H21,0) -> 0 | T21: =IF(E21="Income",H21,0) -> 0
A22: 27/1/26 -> 2/2/26 | B22: Total Reccuring Expenses | H22: =SUMIF(E4:E17,"Recurring Expense",H4:H17) -> 164.99 | N22: =IF(OR(E22="Personal Expense",E22="Recurring Expense"),H22,0) -> 0 | O22: =IF(E22="Internal Transfer",H22,0) -> 0 | P22: =IF(E22="Saving Allocation",H22,0) -> 0 | Q22: =IF(E22="Investment",H22,0) -> 0 | R22: =IF(E22="Debt Repayment",H22,0) -> 0 | S22: =IF(E22="Joint Account",H22,0) -> 0 | T22: =IF(E22="Income",H22,0) -> 0
A23: 27/1/26 -> 2/2/26 | B23: Total Investing | H23: =SUMIF(E4:E17,"Investment",H4:H17) -> 15 | N23: =IF(OR(E23="Personal Expense",E23="Recurring Expense"),H23,0) -> 0 | O23: =IF(E23="Internal Transfer",H23,0) -> 0 | P23: =IF(E23="Saving Allocation",H23,0) -> 0 | Q23: =IF(E23="Investment",H23,0) -> 0 | R23: =IF(E23="Debt Repayment",H23,0) -> 0 | S23: =IF(E23="Joint Account",H23,0) -> 0 | T23: =IF(E23="Income",H23,0) -> 0
A24: 27/1/26 -> 2/2/26 | B24: Total Savings | H24: =SUMIF(E4:E17,"Saving Allocation",H4:H17) -> 200 | N24: =IF(OR(E24="Personal Expense",E24="Recurring Expense"),H24,0) -> 0 | O24: =IF(E24="Internal Transfer",H24,0) -> 0 | P24: =IF(E24="Saving Allocation",H24,0) -> 0 | Q24: =IF(E24="Investment",H24,0) -> 0 | R24: =IF(E24="Debt Repayment",H24,0) -> 0 | S24: =IF(E24="Joint Account",H24,0) -> 0 | T24: =IF(E24="Income",H24,0) -> 0
A25: 27/1/26 -> 2/2/26 | B25: Total Personnal Expenses | H25: =SUMIF(E4:E17,"Personal Expense",H4:H17) -> 243.4 | N25: =IF(OR(E25="Personal Expense",E25="Recurring Expense"),H25,0) -> 0 | O25: =IF(E25="Internal Transfer",H25,0) -> 0 | P25: =IF(E25="Saving Allocation",H25,0) -> 0 | Q25: =IF(E25="Investment",H25,0) -> 0 | R25: =IF(E25="Debt Repayment",H25,0) -> 0 | S25: =IF(E25="Joint Account",H25,0) -> 0 | T25: =IF(E25="Income",H25,0) -> 0
A26: 27/1/26 -> 2/2/26 | G26: Total Debt Repayments | H26: =SUMIF(E4:E17,"Debt Repayment",H4:H17) -> 375 | N26: =IF(OR(E26="Personal Expense",E26="Recurring Expense"),H26,0) -> 0 | O26: =IF(E26="Internal Transfer",H26,0) -> 0 | P26: =IF(E26="Saving Allocation",H26,0) -> 0 | Q26: =IF(E26="Investment",H26,0) -> 0 | R26: =IF(E26="Debt Repayment",H26,0) -> 0 | S26: =IF(E26="Joint Account",H26,0) -> 0 | T26: =IF(E26="Income",H26,0) -> 0
A27: 27/1/26 -> 2/2/26 | G27: TOTAL | H27: =H22+H25+H21+H23+H26+H24 -> 1198.39 | N27: =IF(OR(E27="Personal Expense",E27="Recurring Expense"),H27,0) -> 0 | O27: =IF(E27="Internal Transfer",H27,0) -> 0 | P27: =IF(E27="Saving Allocation",H27,0) -> 0 | Q27: =IF(E27="Investment",H27,0) -> 0 | R27: =IF(E27="Debt Repayment",H27,0) -> 0 | S27: =IF(E27="Joint Account",H27,0) -> 0 | T27: =IF(E27="Income",H27,0) -> 0
A28: 27/1/26 -> 2/2/26 | B28: TRUE WEEKLY SURPLUS | H28: =H20-(H22+H25)-H21-H23-H26-H24 -> 118.36 | N28: =IF(OR(E28="Personal Expense",E28="Recurring Expense"),H28,0) -> 0 | O28: =IF(E28="Internal Transfer",H28,0) -> 0 | P28: =IF(E28="Saving Allocation",H28,0) -> 0 | Q28: =IF(E28="Investment",H28,0) -> 0 | R28: =IF(E28="Debt Repayment",H28,0) -> 0 | S28: =IF(E28="Joint Account",H28,0) -> 0 | T28: =IF(E28="Income",H28,0) -> 0
B29: TRUE WEEKLY SURPLUS W/O SAVINGS | H29: =H28+SUMIFS($H:$H,$A:$A,A28,$E:$E,"Saving Allocation") -> 318.36
A30: 27/1/26 -> 2/2/26 | N30: =IF(OR(E30="Personal Expense",E30="Recurring Expense"),H30,0) -> 0 | O30: =IF(E30="Internal Transfer",H30,0) -> 0 | P30: =IF(E30="Saving Allocation",H30,0) -> 0 | Q30: =IF(E30="Investment",H30,0) -> 0 | R30: =IF(E30="Debt Repayment",H30,0) -> 0 | S30: =IF(E30="Joint Account",H30,0) -> 0 | T30: =IF(E30="Income",H30,0) -> 0
A31: 3/2/26 -> 9/2/26 | B31: 3/2/26 -> 9/2/26 | C31: 46056 | D31: Pay Sapien | E31: Income | F31: Sapien | G31: WestPac Everyday | H31: 1078.75 | I31: Salary | N31: =IF(OR(E31="Personal Expense",E31="Recurring Expense"),H31,0) -> 0 | O31: =IF(E31="Internal Transfer",H31,0) -> 0 | P31: =IF(E31="Saving Allocation",H31,0) -> 0 | Q31: =IF(E31="Investment",H31,0) -> 0 | R31: =IF(E31="Debt Repayment",H31,0) -> 0 | S31: =IF(E31="Joint Account",H31,0) -> 0 | T31: =IF(E31="Income",H31,0) -> 1078.75
A32: 3/2/26 -> 9/2/26 | C32: 46056 | D32: Bills Contribution | E32: Recurring Expense | F32: WestPac Everyday | G32: Lily | H32: 150 | I32: Rent | N32: =IF(OR(E32="Personal Expense",E32="Recurring Expense"),H32,0) -> 150 | O32: =IF(E32="Internal Transfer",H32,0) -> 0 | P32: =IF(E32="Saving Allocation",H32,0) -> 0 | Q32: =IF(E32="Investment",H32,0) -> 0 | R32: =IF(E32="Debt Repayment",H32,0) -> 0 | S32: =IF(E32="Joint Account",H32,0) -> 0 | T32: =IF(E32="Income",H32,0) -> 0
A33: 3/2/26 -> 9/2/26 | C33: 46056 | D33: Reimboursement Lily | E33: Debt Repayment | F33: WestPac Everyday | G33: Lily | H33: 375 | I33: Debt | N33: =IF(OR(E33="Personal Expense",E33="Recurring Expense"),H33,0) -> 0 | O33: =IF(E33="Internal Transfer",H33,0) -> 0 | P33: =IF(E33="Saving Allocation",H33,0) -> 0 | Q33: =IF(E33="Investment",H33,0) -> 0 | R33: =IF(E33="Debt Repayment",H33,0) -> 375 | S33: =IF(E33="Joint Account",H33,0) -> 0 | T33: =IF(E33="Income",H33,0) -> 0
A34: 3/2/26 -> 9/2/26 | C34: 46056 | D34: Transfer To Joint Account | E34: Joint Account | F34: WestPac Everyday | G34: Joint Account | H34: 200 | I34: Housing | N34: =IF(OR(E34="Personal Expense",E34="Recurring Expense"),H34,0) -> 0 | O34: =IF(E34="Internal Transfer",H34,0) -> 0 | P34: =IF(E34="Saving Allocation",H34,0) -> 0 | Q34: =IF(E34="Investment",H34,0) -> 0 | R34: =IF(E34="Debt Repayment",H34,0) -> 0 | S34: =IF(E34="Joint Account",H34,0) -> 200 | T34: =IF(E34="Income",H34,0) -> 0
A35: 3/2/26 -> 9/2/26 | C35: 46057 | D35: BTC Buy | E35: Investment | F35: WestPac Everyday | G35: OKX | H35: 15 | I35: Investment | N35: =IF(OR(E35="Personal Expense",E35="Recurring Expense"),H35,0) -> 0 | O35: =IF(E35="Internal Transfer",H35,0) -> 0 | P35: =IF(E35="Saving Allocation",H35,0) -> 0 | Q35: =IF(E35="Investment",H35,0) -> 15 | R35: =IF(E35="Debt Repayment",H35,0) -> 0 | S35: =IF(E35="Joint Account",H35,0) -> 0 | T35: =IF(E35="Income",H35,0) -> 0
A36: 3/2/26 -> 9/2/26 | C36: 46057 | D36: Dentist | E36: Personal Expense | F36: WestPac Everyday | G36: External | H36: 80 | I36: Repayment | N36: =IF(OR(E36="Personal Expense",E36="Recurring Expense"),H36,0) -> 80 | O36: =IF(E36="Internal Transfer",H36,0) -> 0 | P36: =IF(E36="Saving Allocation",H36,0) -> 0 | Q36: =IF(E36="Investment",H36,0) -> 0 | R36: =IF(E36="Debt Repayment",H36,0) -> 0 | S36: =IF(E36="Joint Account",H36,0) -> 0 | T36: =IF(E36="Income",H36,0) -> 0
A37: 3/2/26 -> 9/2/26 | C37: 46057 | D37: Buffer for Emerg. Cash | E37: Saving Allocation | F37: WestPac Everyday | G37: Emergency Fund | H37: 130 | I37: Savings | N37: =IF(OR(E37="Personal Expense",E37="Recurring Expense"),H37,0) -> 0 | O37: =IF(E37="Internal Transfer",H37,0) -> 0 | P37: =IF(E37="Saving Allocation",H37,0) -> 130 | Q37: =IF(E37="Investment",H37,0) -> 0 | R37: =IF(E37="Debt Repayment",H37,0) -> 0 | S37: =IF(E37="Joint Account",H37,0) -> 0 | T37: =IF(E37="Income",H37,0) -> 0
A38: 3/2/26 -> 9/2/26 | C38: 46061 | D38: Transfer To Joint Account | E38: Joint Account | F38: WestPac Everyday | G38: Joint Account | H38: 50 | I38: Housing | N38: =IF(OR(E38="Personal Expense",E38="Recurring Expense"),H38,0) -> 0 | O38: =IF(E38="Internal Transfer",H38,0) -> 0 | P38: =IF(E38="Saving Allocation",H38,0) -> 0 | Q38: =IF(E38="Investment",H38,0) -> 0 | R38: =IF(E38="Debt Repayment",H38,0) -> 0 | S38: =IF(E38="Joint Account",H38,0) -> 50 | T38: =IF(E38="Income",H38,0) -> 0
A39: 3/2/26 -> 9/2/26 | C39: 46062 | D39: Sandwich at Work | E39: Personal Expense | F39: WestPac Everyday | G39: External | H39: 7.63 | I39: Food/Drink | N39: =IF(OR(E39="Personal Expense",E39="Recurring Expense"),H39,0) -> 7.63 | O39: =IF(E39="Internal Transfer",H39,0) -> 0 | P39: =IF(E39="Saving Allocation",H39,0) -> 0 | Q39: =IF(E39="Investment",H39,0) -> 0 | R39: =IF(E39="Debt Repayment",H39,0) -> 0 | S39: =IF(E39="Joint Account",H39,0) -> 0 | T39: =IF(E39="Income",H39,0) -> 0
A40: 3/2/26 -> 9/2/26 | N40: =IF(OR(E40="Personal Expense",E40="Recurring Expense"),H40,0) -> 0 | O40: =IF(E40="Internal Transfer",H40,0) -> 0 | P40: =IF(E40="Saving Allocation",H40,0) -> 0 | Q40: =IF(E40="Investment",H40,0) -> 0 | R40: =IF(E40="Debt Repayment",H40,0) -> 0 | S40: =IF(E40="Joint Account",H40,0) -> 0 | T40: =IF(E40="Income",H40,0) -> 0
A41: 3/2/26 -> 9/2/26 | B41: Pay | H41: =SUMIF(E31:E39,"Income",H31:H39) -> 1078.75 | N41: =IF(OR(E41="Personal Expense",E41="Recurring Expense"),H41,0) -> 0 | O41: =IF(E41="Internal Transfer",H41,0) -> 0 | P41: =IF(E41="Saving Allocation",H41,0) -> 0 | Q41: =IF(E41="Investment",H41,0) -> 0 | R41: =IF(E41="Debt Repayment",H41,0) -> 0 | S41: =IF(E41="Joint Account",H41,0) -> 0 | T41: =IF(E41="Income",H41,0) -> 0
...

Sheet Work Income Tracker
B4: Driscoll's INCOME TRACKER (Farm Mandatory Job)
B5: TIME RELATED | G5: BASE RATE | H5: PAY RELATED | K5: NOTES | L5: TAXE RELATED | N5: SUPERANNUATION
B6: Weeks Count | C6: Driscolls | D6: Days Worked | E6: Hours / Day | F6: Hours Worked | G6: Base Rate in AU$ | H6: Gross Weekly income in AU$ | I6: Net Weekly income in AU$ | J6: Monthly Income in AU$ | K6: Notes | L6: PAYG (Tax Withheld) | M6: PAYG (%) | N6: UniSuper
B7: 1st | C7: 45455 | D7: 3 | E7: =IFERROR(F7/D7,"") -> 7 | F7: 21 | G7: 28.26 | H7: =(G7*F7) -> 593.46 | I7: 504.46 | K7: $245 fees (Rent+Transport) / $259.46 Net | L7: =H7-I7 -> 89 | M7: =(H7-I7)/H7 -> 0.14996798 | N7: 65.28
B8: 2nd | C8: 45462 | D8: 4 | E8: =IFERROR(F8/D8,"") -> 7.125 | F8: 28.5 | G8: 28.26 | H8: =(G8*F8) -> 805.41 | I8: 684.41 | K8: $245 fees (Rent+Transport) / $439.41 Net | L8: =H8-I8 -> 121 | M8: =(H8-I8)/H8 -> 0.15023404 | N8: 88.6
B9: 3rd | C9: 45469 | D9: 5 | E9: =IFERROR(F9/D9,"") -> 7.5 | F9: 37.5 | G9: 28.26 | H9: =(G9*F9) -> 1059.75 | I9: 900.75 | K9: $245 fees (Rent+Transport) / $655.75 Net | L9: =H9-I9 -> 159 | M9: =(H9-I9)/H9 -> 0.15003539 | N9: 116.57
B10: 4th | C10: 45476 | D10: 5 | E10: =IFERROR(F10/D10,"") -> 7.5 | F10: 37.5 | G10: 28.26 | H10: =(G10*F10) -> 1059.75 | I10: 900.75 | J10: =SUM(I7:I10) -> 2990.37 | K10: $245 fees (Rent+Transport) / $655.75 Net | L10: =H10-I10 -> 159 | M10: =(H10-I10)/H10 -> 0.15003539 | N10: 121.87
B11: NEW FINANCIAL YEAR
B12: 5th | C12: 45483 | D12: 5 | E12: =IFERROR(F12/D12,"") -> 7.5 | F12: 37.5 | G12: 29.33 | H12: =(G12*F12) -> 1099.875 | I12: 934.88 | K12: $245 fees (Rent+Transport) / $689.88 Net | L12: =H12-I12 -> 164.995 | M12: =(H12-I12)/H12 -> 0.1500125 | N12: 126.49
B13: 6th | C13: 45490 | D13: 5 | E13: =IFERROR(F13/D13,"") -> 7.5 | F13: 37.5 | G13: 29.33 | H13: =(G13*F13) -> 1099.875 | I13: 934.88 | L13: =H13-I13 -> 164.995 | M13: =(H13-I13)/H13 -> 0.1500125 | N13: 126.49
B14: 7th | C14: 45497 | D14: 5 | E14: =IFERROR(F14/D14,"") -> 7.5 | F14: 37.5 | G14: 29.33 | H14: =((G14*F14)+(G15*F15)+(G16*F16)) -> 1328.635 | I14: 1129.64 | K14: 5 Extra Hours during the week | L14: =(SUM(H14:H16)-I14) -> 198.995 | M14: =((H14+H15+H16)-I14)/(H14+H15+H16) -> 0.14977402 | N14: 126.49
D15: 0 | E15: =IFERROR(F15/D15,"") | F15: 3 | G15: 41.06
D16: 0 | E16: =IFERROR(F16/D16,"") | F16: 2 | G16: 52.79
B17: 8th | C17: 45504 | D17: 5 | E17: =IFERROR(F17/D17,"") -> 7.5 | F17: 37.5 | G17: 29.33 | H17: =(G17*F17) -> 1099.875 | I17: 934.88 | J17: =SUM(I12:I17) -> 3934.28 | L17: =H17-I17 -> 164.995 | M17: =(H17-I17)/H17 -> 0.1500125 | N17: 126.49
B18: 9th | C18: 45511 | D18: 5 | E18: =IFERROR(F18/D18,"") -> 7.5 | F18: 37.5 | G18: 29.33 | H18: =(G18*F18) -> 1099.875 | I18: 934.88 | L18: =H18-I18 -> 164.995 | M18: =(H18-I18)/H18 -> 0.1500125 | N18: 126.49
B19: 10th | C19: 45518 | D19: 5 | E19: =IFERROR(F19/D19,"") -> 7.5 | F19: 37.5 | G19: 29.33 | H19: =(G19*F19) -> 1099.875 | I19: 934.88 | L19: =H19-I19 -> 164.995 | M19: =(H19-I19)/H19 -> 0.1500125 | N19: 126.49
B20: 11th | C20: 45525 | D20: 5 | E20: =IFERROR(F20/D20,"") -> 7.5 | F20: 37.5 | G20: 29.33 | H20: =G20*F20 -> 1099.875 | I20: 934.88 | L20: =H20-I20 -> 164.995 | M20: =(H20-I20)/H20 -> 0.1500125 | N20: 126.49
B21: 12th | C21: 45532 | D21: 4 | E21: =IFERROR(F21/D21,"") -> 6.875 | F21: 27.5 | G21: 29.33 | H21: =G21*F21 -> 806.575 | I21: 685 | J21: =SUM(I18:I21) -> 3489.64 | K21: Fired on the Thursday at lunchtime | L21: =H21-I21 -> 121.575 | M21: =(H21-I21)/H21 -> 0.15072994 | N21: 93.11
B22: / | C22: AVERAGE | D22: =AVERAGE(D7:D10,D12:D14,D17:D21) -> 4.6666667 | E22: =AVERAGE(E7:E10,E12:E14,E17:E21) -> 7.375 | F22: =AVERAGE(F7:F10,F12:F14,F17:F21) -> 34.541667 | G22: =AVERAGE(G7:G10,G12:G14,G17:G21) -> 28.973333 | H22: =AVERAGE(H7:H21) -> 1021.0692 | I22: =AVERAGE(I7:I21) -> 867.8575 | J22: =AVERAGE(J7:J18,J20:J21) -> 3471.43 | K22: / | L22: =AVERAGE(L7:L21) -> 153.21167 | M22: =AVERAGE(M1:M21) -> 0.15007098 | N22: /
B23: / | C23: TOTAL | D23: =SUM(D7:D10,D12:D14,D17:D21) -> 56 | E23: / | F23: =SUM(F7:F21) -> 419.5 | G23: / | H23: =SUM(H7:H21) -> 12252.83 | I23: =SUM(I7:I21) -> 10414.29 | J23: / | K23: / | L23: =SUM(L7:L19,L20:L21) -> 1838.54 | M23: / | N23: =SUM(N7:N21) -> 1370.86
B26: Tamarua (Perth) INCOME TRACKER (Farm Mandatory Job)
B27: TIME RELATED | G27: BASE RATE | H27: PAY RELATED | K27: NOTES | L27: TAXE RELATED | N27: SUPERANNUATION
B28: Weeks Count | C28: Tamarua | D28: Days Worked | E28: Hours / Day | F28: Hours Worked | G28: Base Rate in AU$ | H28: Gross Fortnight income in AU$ | I28: Net Fornight income in AU$ | J28: Monthly Income in AU$ | K28: Notes | L28: PAYG (Tax Withheld) | M28: PAYG (%) | N28: UniSuper
B29: 1st + 2nd | C29: 45547 | D29: 14 | E29: =IFERROR(F29/D29,"") -> 4.9635714 | F29: 69.49 | G29: 30 | H29: =(G29*F29) -> 2084.7 | I29: 1771.7 | L29: =H29-I29 -> 313 | M29: =(H29-I29)/H29 -> 0.15014151 | N29: 239.74
B30: 3rd + 4th | C30: 45561 | D30: 14 | E30: =IFERROR(F30/D30,"") -> 5.6092857 | F30: 78.53 | G30: 30 | H30: =(G30*F30) -> 2355.9 | I30: 2002.9 | L30: =H30-I30 -> 353 | M30: =(H30-I30)/H30 -> 0.14983658 | N30: 270.93
B31: 5th + 6th | C31: 45575 | D31: 14 | E31: =IFERROR(F31/D31,"") -> 7.8585714 | F31: 110.02 | G31: 30 | H31: 3300.6 | I31: 2805.6 | J31: =SUM(I29:I31) -> 6580.2 | L31: =H31-I31 -> 495 | N31: 379.57
B32: / | C32: AVERAGE | D32: =AVERAGE(D29:D31) -> 14 | E32: =AVERAGE(E29:E31) -> 6.1438095 | F32: =AVERAGE(F29:F31) -> 86.013333 | G32: =AVERAGE(G29:G30) -> 30 | H32: =AVERAGE(H29:H31) -> 2580.4 | I32: =AVERAGE(I29:I31) -> 2193.4 | J32: / | K32: / | L32: =AVERAGE(L29:L31) -> 387 | M32: =AVERAGE(M25:M30) -> 0.14998904 | N32: /
B33: / | C33: TOTAL | D33: =SUM(D29:D31) -> 42 | E33: / | F33: =SUM(F29:F31) -> 258.04 | G33: / | H33: =SUM(H29:H31) -> 7741.2 | I33: =SUM(I29:I31) -> 6580.2 | J33: =SUM(J29:J31) -> 6580.2 | K33: / | L33: =SUM(L29:L31) -> 1161 | M33: / | N33: =SUM(N29:N31) -> 890.24
B36: Consolidated Carpentry INCOME TRACKER
B37: TIME RELATED | H37: BASE RATE | I37: PAY RELATED | L37: NOTES | M37: TAXE RELATED | P37: SUPERANNUATION
B38: Weeks Count | C38: Consolidated Carpentry | D38: Days Worked | E38: Hours / Day | F38: Hours Worked | G38: With extra hours | H38: Base Rate in AU$ | I38: Gross Weekly income in AU$ | J38: Net Weekly income in AU$ | K38: Monthly Income in AU$ | L38: Notes | M38: PAYG (Tax Withheld) | N38: PAYG (%) | O38: Tax to Pay on ABN | P38: UniSuper
B39: 1st | C39: 45683 | D39: 5 | E39: =IFERROR(F39/D39,"") -> 6.6 | F39: 33 | G39: 33 | H39: 25.9 | I39: =(H39*F39) -> 854.7 | J39: 598.7 | M39: =I39-J39 -> 256 | N39: =(I39-J39)/I39 -> 0.2995203 | O39: / | P39: 98.29
B40: 2nd | C40: 45690 | D40: 5 | E40: =IFERROR(F40/D40,"") -> 6 | F40: 30 | G40: =SUM(F40:F42) -> 36 | H40: 25.9 | I40: =((H40*F40)+(H41*F41)+(H42*F42)) -> 1061.9 | J40: 743.9 | L40: 6 Extra Hours During the week | M40: =I40-J40 -> 318 | N40: =(I40-J40)/I40 -> 0.29946323 | O40: / | P40: 89.36
D41: 1 | E41: =IFERROR(F41/D41,"") -> 2 | F41: 2 | H41: 38.85
D42: 1 | E42: =IFERROR(F42/D42,"") -> 4 | F42: 4 | H42: 51.8
B43: 3rd | C43: 45697 | D43: 5 | E43: =IFERROR(F43/D43,"") -> 7.6 | F43: 38 | G43: 38 | H43: 25.9 | I43: =(H43*F43) -> 984.2 | J43: 836.2 | M43: =I43-J43 -> 148 | N43: =(I43-J43)/I43 -> 0.15037594 | O43: / | P43: 113.18
B44: 4th | C44: 45704 | D44: 5 | E44: =IFERROR(F44/D44,"") -> 7.6 | F44: 38 | G44: =SUM(F44:F45) -> 39 | H44: 25.9 | I44: =((H44*F44)+(H45*F45)) -> 1023.05 | J44: 870.05 | K44: =SUM(J39:J45) -> 3048.85 | L44: 1 Extra Hour during the week | M44: =I44-J44 -> 153 | N44: =(I44-J44)/I44 -> 0.14955281 | O44: / | P44: 113.18
D45: 0 | E45: =IFERROR(F45/D45,"") | F45: 1 | H45: 38.85
B46: 5th | C46: 45711 | D46: 5 | E46: =IFERROR(F46/D46,"") -> 7.6 | F46: 38 | G46: =SUM(F46:F48) -> 55.5 | H46: 25.9 | I46: =((H46*F46)+(H47*F47)+(H48*F48)) -> 1800.05 | J46: 1530.05 | L46: 17.5 Extra Hours during the week | M46: =I46-J46 -> 270 | N46: =(I46-J46)/I46 -> 0.14999583 | O46: / | P46: 113.18
D47: 1 | E47: =IFERROR(F47/D47,"") -> 7 | F47: 7 | H47: 38.85
...

Sheet Investing
A2: CRYPTOCURRENCY | H2: ASX ETF | T2: ASX STOCK PICKING | Z2: WALL STREET STOCK PICKING
B4: BITCOIN INVESTMENT | H4: BGBL INVESTMENT (ASX) | N4: VGE INVESTMENT (ASX) | T4: CSL INVESTMENT (ASX) | Z4: VOO INVESTMENT (S&P 500)
B5: Date | C5: Amount Invested | D5: Amount Bitcoin | E5: Bitcoin Price | H5: Date | I5: Amount Invested | J5: Shares Amount | K5: Share Price | N5: Date | O5: Amount Invested | P5: Shares Amount | Q5: Share Price | T5: Date | U5: Amount Invested | V5: Amount shares | W5: Share Price | Z5: Date | AA5: Amount Invested | AB5: Amount Shares | AC5: Share Price
B6: 45952 | C6: 40 | D6: 0.00023653 | E6: 168492 | H6: 46125 | I6: 80 | J6: 1.037 | K6: 77.14 | N6: 46125 | O6: 20 | P6: 0.2278 | Q6: 87.76 | T6: 46133 | U6: 30 | V6: 0.22 | W6: 136.34 | Z6: 46135 | AA6: 67.52 | AB6: 0.0989 | AC6: 652.35
B7: 45958 | C7: 0 | D7: 0.0004357 | E7: 171542 | H7: 46128 | I7: 80 | J7: 1.0198 | K7: 78.44 | N7: 46128 | O7: 20 | P7: 0.2227 | Q7: 89.8
B8: 45960 | C8: 14 | D8: 8.172e-05 | E8: 171301 | H8: 46134 | I8: 80 | J8: 1.0134 | K8: 78.94 | N8: 46134 | O8: 20 | P8: 0.2205 | Q8: 90.69
B9: 45966 | C9: 35 | D9: 0.00022173 | E9: 157000 | H9: 46140 | I9: 28 | J9: 0.354 | K9: 79.09 | N9: 46140 | O9: 10 | P9: 0.1108 | Q9: 90.24 | T9: Total Bought (Buy) | U9: =SUM(U6:U8) -> 30 | V9: =SUM(V6:V8) -> 0.22 | W9: =U9/V9 -> 136.36364 | X9: <- AVERAGE PRICE BOUGHT | Z9: Total Bought (Buy) | AA9: =SUM(AA6:AA8) -> 67.52 | AB9: =SUM(AB6:AB8) -> 0.0989 | AC9: =AVERAGE(AC6:AC8) -> 652.35 | AD9: <- AVERAGE PRICE BOUGHT
B10: 45976 | C10: 10 | D10: 6.763e-05 | E10: 147851.7 | H10: 46148 | I10: 25 | J10: 0.3129 | K10: 79.89 | N10: 46148 | O10: 10 | P10: 0.1093 | Q10: 91.44 | T10: Current Price / Value | U10: =V9*W10 -> 21.5512 | W10: {=_xlfn.FIELDVALUE(U11,"Price")} -> 97.96 | Z10: Current Price / Value in USD | AA10: =AB9*AC10 -> 67.196616 | AC10: {=_xlfn.FIELDVALUE(AA12,"Price")} -> 679.44
B11: 45981 | C11: 30 | D11: 0.00021373 | E11: 140363.8 | H11: 46155 | I11: 25 | J11: 0.3083 | K11: 81.06 | N11: 46155 | O11: 10 | P11: 0.1091 | Q11: 91.64 | T11: Current Price | U11: #VALUE! | Z11: Current Price / Value in AUD | AA11: =AA10*AB15 -> 93.940869
B12: 45982 | C12: 30 | D12: 0.00022143 | E12: 134426.2 | T12: P/L | U12: =U10-U9 -> -8.4488 | Z12: Current Price | AA12: #VALUE!
B13: 46049 | C13: 14.99 | D13: 0.00011727 | E13: 127000 | T13: ROI | U13: =U12/U9 -> -0.28162667 | Z13: P/L | AA13: =AA10-AA9 -> -0.323384
B14: 46058 | C14: 14.99 | D14: 0.00013842 | E14: 107600 | Z14: ROI | AA14: =AA13/AA9 -> -0.004789455
B15: 46076 | C15: 14.99 | D15: 0.00015669 | E15: 95000 | Z15: USD/AUD | AA15: #VALUE! | AB15: {=_xlfn.FIELDVALUE(AA15,"Price")} -> 1.398
B16: 46099 | C16: 14.99 | D16: 0.00014319 | E16: 104000 | H16: Total Bought | I16: =SUM(I6:I15) -> 318 | J16: =SUM(J6:J15) -> 4.0454 | K16: =AVERAGE(K6:K15) -> 79.093333 | L16: <- AVERAGE PRICE BOUGHT | N16: Total Bought | O16: =SUM(O6:O15) -> 90 | P16: =SUM(P6:P15) -> 1.0002 | Q16: =AVERAGE(Q6:Q15) -> 90.261667 | R16: <- AVERAGE PRICE BOUGHT
B17: 46100 | C17: 14.99 | D17: 0.00014597 | E17: 102000 | H17: Curent Price / Value | I17: =J16*K17 -> 329.98328 | K17: {=_xlfn.FIELDVALUE(I18,"Price")} -> 81.57 | N17: Curent Price / Value | O17: =P16*Q17 -> 90.088014 | Q17: {=_xlfn.FIELDVALUE(O18,"Price")} -> 90.07
B18: 46100 | C18: 14.99 | D18: 0.00014895 | E18: 100000 | H18: BGBL VALUE REAL TIME | I18: #VALUE! | N18: BGBL VALUE REAL TIME | O18: #VALUE!
B19: 46103 | C19: 14.99 | D19: 0.00015113 | E19: 98000 | H19: P/L | I19: =I17-I16 -> 11.983278 | N19: P/L | O19: =O17-O16 -> 0.088014
B20: 46114 | C20: 14.99 | D20: 0.00015192 | E20: 98000 | H20: ROI | I20: =I19/I16 -> 0.037683264 | N20: ROI | O20: =O19/O16 -> 0.00097793333
B21: 46125 | C21: 14.99 | D21: 0.00014348 | E21: 101000
B22: 46128 | C22: 14.99 | D22: 0.00014438 | E22: 102500
B23: 46136 | C23: 14.99 | D23: 0.00013574 | E23: 109727
B24: 46140 | C24: 14.99 | D24: 0.00013743 | E24: 108341.7
B25: 46148 | C25: 14.99 | D25: 0.00013147 | E25: 113219.6
B26: 46155 | C26: 14.99 | D26: 0.00013604 | E26: 109431.6
B29: Total BTC Owned (ALL) | D29: =SUM(D6:D28) -> 0.00346055
B30: Total BTC Bought (Buy) | C30: =SUM(C6:C28) -> 368.86 | D30: =SUM(D8:D28,D6) -> 0.00302485 | E30: =AVERAGE(E6,E8:E28) -> 119762.73 | F30: <- AVERAGE PRICE BOUGHT
B31: Current Price / Value | C31: =D30*E31 -> 330.21314 | E31: {=_xlfn.FIELDVALUE(C32,"Price")} -> 109166.78
B32: BTC VALUE REAL TIME | C32: #VALUE!
B33: P/L | C33: =C31-C30 -> -38.646856
B34: ROI | C34: =C33/C30 -> -0.10477378

Sheet Stock Picking Scorecard
B2: STOCK PICKING SCORECARD | J2: BARÈME / RÈGLES
B3: SCORECARD | J3: GUIDE RAPIDE
B4: Critère | C4: Poids | D4: Score (0-5) | E4: Score pondéré | F4: Passage | G4: Notes | H4: Question clé | J4: Score | K4: Sens | L4: Lecture | M4: Action
B5: Qualité du business | C5: 20 | D5: 4.5 | E5: =C5*D5/5 -> 18 | F5: =IF(D5="","",IF(D5>=4,"Strong",IF(D5>=3,"OK","Weak"))) -> Strong | H5: Le business est-il compréhensible, utile et défendable? | J5: 0 | K5: Très mauvais | L5: Faiblesse majeure / incompréhension | M5: Stop
B6: Position concurrentielle | C6: 15 | D6: 4.5 | E6: =C6*D6/5 -> 13.5 | F6: =IF(D6="","",IF(D6>=4,"Strong",IF(D6>=3,"OK","Weak"))) -> Strong | H6: Pourquoi elle plutôt qu’un concurrent ? | J6: 1 | K6: Faible | L6: Problème sérieux | M6: Écarter
B7: Management & allocation du capital | C7: 15 | D7: 3 | E7: =C7*D7/5 -> 9 | F7: =IF(D7="","",IF(D7>=4,"Strong",IF(D7>=3,"OK","Weak"))) -> OK | H7: Le CEO/board gèrent-ils bien le capital ? | J7: 2 | K7: Moyen faible | L7: Peu convaincant | M7: Watchlist seulement
B8: Qualité financière | C8: 20 | D8: 4 | E8: =C8*D8/5 -> 16 | F8: =IF(D8="","",IF(D8>=4,"Strong",IF(D8>=3,"OK","Weak"))) -> Strong | H8: Le profit, le cash et le bilan sont-ils solides ? | J8: 3 | K8: Acceptable | L8: Base correcte | M8: Creuser davantage
B9: Résilience & risques | C9: 15 | D9: 3.5 | E9: =C9*D9/5 -> 10.5 | F9: =IF(D9="","",IF(D9>=4,"Strong",IF(D9>=3,"OK","Weak"))) -> OK | H9: Peut-elle absorber un choc sans casser la thèse ? | J9: 4 | K9: Bon | L9: Thèse solide | M9: Candidat sérieux
B10: Valorisation | C10: 15 | D10: 3.5 | E10: =C10*D10/5 -> 10.5 | F10: =IF(D10="","",IF(D10>=4,"Strong",IF(D10>=3,"OK","Weak"))) -> OK | H10: Le prix payé laisse-t-il une marge d’erreur ? | J10: 5 | K10: Très bon | L10: Qualité + prix | M10: Achat possible
B12: Total Score | D12: =SUM(E5:E10) -> 77.5 | J12: SEUILS
B13: Verdict | D13: =IF(D12="","",IF(D12>=80,"Très bon dossier",IF(D12>=70,"Bon dossier",IF(D12>=60,"Moyen / prix très important","Non pour l’instant")))) -> Bon dossier | J13: 80+ = Très bon dossier
B14: Red Flag fatale ? | D14: Non | E14: Si Oui, pas d’achat | J14: 70-79 = Bon dossier
B15: Décision | D15: =IF(OR(D14="Oui",D12=""),"",IF(D12>=80,"Achat possible / surveillance active",IF(D12>=70,"Surveiller ou petite ligne",IF(D12>=60,"Watchlist seulement","Rejeter pour l’instant")))) -> Surveiller ou petite ligne | J15: 60-69 = Moyen / prix très important
J16: <60 = Non pour l’instant
B17: RÈGLE : je n’achète pas une baisse. J’achète une thèse, un business et un prix.
J18: HARD STOPS
J19: • Business non compris
J20: • Bilan dangereux / dette excessive
J21: • Management douteux ou destructeur de capital
J22: • Pas de marge de sécurité
J23: • Thèse non écrite avant achat
